<?xml version="1.0"?>
<robot>
    <macro name="link_wheel" params="name">
        <link name="${name}">
            <inertial>
              <mass value="0.8"/>
              <origin rpy="0 1.5707 0" xyz="0 0 0"/>
              <inertia ixx="0.04466666" ixy="0" ixz="0" iyy="0.04466666" iyz="0" izz="0.004"/>
            </inertial>
            <collision name="link_right_wheel_collision">
              <origin rpy="0 1.5707 0" xyz="0 0 0"/>
              <geometry>
                <cylinder length="0.08" radius="0.1"/>
              </geometry>
      		<surface>
        	  <friction>
          	    <ode>
            		<mu>0.1</mu>
            		<mu2>0.1</mu2>
          	    </ode>
        	  </friction>
      		</surface>
            </collision>
            <visual name="${name}_visual">
              <origin rpy="0 1.5707 0" xyz="0 0 0"/>
              <geometry>
                <cylinder length="0.08" radius="0.1"/>
              </geometry>
            </visual>
        </link>
    </macro>

    <macro name="joint_wheel" params="name child origin_xyz">
      <joint name="${name}" type="continuous">
        <origin rpy="0 0 0" xyz="${origin_xyz}"/>
        <child link="${child}"/>
        <parent link="link_chassis"/>
        <axis rpy="0 0 0" xyz="1 0 0"/>
        <limit effort="10000" velocity="1000"/>
        <joint_properties damping="1.0" friction="1.0"/>
      </joint>
    </macro>

    <macro name="cylinder_inertia" params="mass r l">
        <inertia  ixx="${mass*(3*r*r+l*l)/12}" ixy = "0" ixz = "0"
                  iyy="${mass*(3*r*r+l*l)/12}" iyz = "0"
                  izz="${mass*(r*r)/2}" />
    </macro>

</robot>
